<?xml version="1.0" encoding="UTF-8"?>
<!-- Generated by org.testng.reporters.JUnitReportReporter -->
<testsuite hostname="DESKTOP-HSNMEPH" failures="2" tests="6" name="com.nexsoft.jcb.test.TestFiturAddNewDataPage" time="83.758" errors="0" timestamp="2022-07-14T23:41:05 ICT" skipped="0">
  <testcase classname="com.nexsoft.jcb.test.TestFiturAddNewDataPage" name="add_New_Data_with_valid_data1" time="13.189"/>
  <system-out/>
  <testcase classname="com.nexsoft.jcb.test.TestFiturAddNewDataPage" name="add_New_Data_with_valid_data2" time="14.424"/>
  <system-out/>
  <testcase classname="com.nexsoft.jcb.test.TestFiturAddNewDataPage" name="add_New_Data_with_valid_data3" time="14.139"/>
  <system-out/>
  <testcase classname="com.nexsoft.jcb.test.TestFiturAddNewDataPage" name="add_New_Data_with_valid_data4" time="16.358"/>
  <system-out/>
  <testcase classname="com.nexsoft.jcb.test.TestFiturAddNewDataPage" name="add_New_Data_with_invalid_data1" time="13.448">
    <failure message="Seharusnya data tidak berhasil disimpan,karena data inputan tidak valid(tidak ada validasi untuk field input Merchant Name) expected [true] but found [false]" type="java.lang.AssertionError">
      <![CDATA[java.lang.AssertionError: Seharusnya data tidak berhasil disimpan,karena data inputan tidak valid(tidak ada validasi untuk field input Merchant Name) expected [true] but found [false]
at org.testng.Assert.fail(Assert.java:110)
at org.testng.Assert.failNotEquals(Assert.java:1413)
at org.testng.Assert.assertTrue(Assert.java:56)
at com.nexsoft.jcb.test.TestFiturAddNewDataPage.add_New_Data_with_invalid_data1(TestFiturAddNewDataPage.java:285)
at java.base/jdk.internal.reflect.NativeMethodAccessorImpl.invoke0(Native Method)
at java.base/jdk.internal.reflect.NativeMethodAccessorImpl.invoke(NativeMethodAccessorImpl.java:62)
at java.base/jdk.internal.reflect.DelegatingMethodAccessorImpl.invoke(DelegatingMethodAccessorImpl.java:43)
at java.base/java.lang.reflect.Method.invoke(Method.java:566)
at org.testng.internal.invokers.MethodInvocationHelper.invokeMethod(MethodInvocationHelper.java:139)
at org.testng.internal.invokers.TestInvoker.invokeMethod(TestInvoker.java:677)
at org.testng.internal.invokers.TestInvoker.invokeTestMethod(TestInvoker.java:221)
at org.testng.internal.invokers.MethodRunner.runInSequence(MethodRunner.java:50)
at org.testng.internal.invokers.TestInvoker$MethodInvocationAgent.invoke(TestInvoker.java:962)
at org.testng.internal.invokers.TestInvoker.invokeTestMethods(TestInvoker.java:194)
at org.testng.internal.invokers.TestMethodWorker.invokeTestMethods(TestMethodWorker.java:148)
at org.testng.internal.invokers.TestMethodWorker.run(TestMethodWorker.java:128)
at java.base/java.util.ArrayList.forEach(ArrayList.java:1541)
at org.testng.TestRunner.privateRun(TestRunner.java:806)
at org.testng.TestRunner.run(TestRunner.java:601)
at org.testng.SuiteRunner.runTest(SuiteRunner.java:433)
at org.testng.SuiteRunner.runSequentially(SuiteRunner.java:427)
at org.testng.SuiteRunner.privateRun(SuiteRunner.java:387)
at org.testng.SuiteRunner.run(SuiteRunner.java:330)
at org.testng.SuiteRunnerWorker.runSuite(SuiteRunnerWorker.java:52)
at org.testng.SuiteRunnerWorker.run(SuiteRunnerWorker.java:95)
at org.testng.TestNG.runSuitesSequentially(TestNG.java:1256)
at org.testng.TestNG.runSuitesLocally(TestNG.java:1176)
at org.testng.TestNG.runSuites(TestNG.java:1099)
at org.testng.TestNG.run(TestNG.java:1067)
at org.testng.remote.AbstractRemoteTestNG.run(AbstractRemoteTestNG.java:115)
at org.testng.remote.RemoteTestNG.initAndRun(RemoteTestNG.java:251)
at org.testng.remote.RemoteTestNG.main(RemoteTestNG.java:77)
]]>
    </failure>
  </testcase> <!-- add_New_Data_with_invalid_data1 -->
  <system-out>
    <![CDATA[<img src='file://D:\Bootcamp\jcb\Screenshot\Error_20220714_231104.PNG'height="350" width="792"/>
<img src='file://D:\Bootcamp\jcb\Screenshot\Error_20220714_231105.PNG'height="350" width="792"/>]]>
  </system-out>
  <testcase classname="com.nexsoft.jcb.test.TestFiturAddNewDataPage" name="add_New_Data_with_invalid_data2" time="12.200">
    <failure message="Seharusnya data tidak berhasil disimpan,karena data inputan tidak valid(tidak ada validasi untuk field input PIC dan No Telp PIC) expected [true] but found [false]" type="java.lang.AssertionError">
      <![CDATA[java.lang.AssertionError: Seharusnya data tidak berhasil disimpan,karena data inputan tidak valid(tidak ada validasi untuk field input PIC dan No Telp PIC) expected [true] but found [false]
at org.testng.Assert.fail(Assert.java:110)
at org.testng.Assert.failNotEquals(Assert.java:1413)
at org.testng.Assert.assertTrue(Assert.java:56)
at com.nexsoft.jcb.test.TestFiturAddNewDataPage.add_New_Data_with_invalid_data2(TestFiturAddNewDataPage.java:331)
at java.base/jdk.internal.reflect.NativeMethodAccessorImpl.invoke0(Native Method)
at java.base/jdk.internal.reflect.NativeMethodAccessorImpl.invoke(NativeMethodAccessorImpl.java:62)
at java.base/jdk.internal.reflect.DelegatingMethodAccessorImpl.invoke(DelegatingMethodAccessorImpl.java:43)
at java.base/java.lang.reflect.Method.invoke(Method.java:566)
at org.testng.internal.invokers.MethodInvocationHelper.invokeMethod(MethodInvocationHelper.java:139)
at org.testng.internal.invokers.TestInvoker.invokeMethod(TestInvoker.java:677)
at org.testng.internal.invokers.TestInvoker.invokeTestMethod(TestInvoker.java:221)
at org.testng.internal.invokers.MethodRunner.runInSequence(MethodRunner.java:50)
at org.testng.internal.invokers.TestInvoker$MethodInvocationAgent.invoke(TestInvoker.java:962)
at org.testng.internal.invokers.TestInvoker.invokeTestMethods(TestInvoker.java:194)
at org.testng.internal.invokers.TestMethodWorker.invokeTestMethods(TestMethodWorker.java:148)
at org.testng.internal.invokers.TestMethodWorker.run(TestMethodWorker.java:128)
at java.base/java.util.ArrayList.forEach(ArrayList.java:1541)
at org.testng.TestRunner.privateRun(TestRunner.java:806)
at org.testng.TestRunner.run(TestRunner.java:601)
at org.testng.SuiteRunner.runTest(SuiteRunner.java:433)
at org.testng.SuiteRunner.runSequentially(SuiteRunner.java:427)
at org.testng.SuiteRunner.privateRun(SuiteRunner.java:387)
at org.testng.SuiteRunner.run(SuiteRunner.java:330)
at org.testng.SuiteRunnerWorker.runSuite(SuiteRunnerWorker.java:52)
at org.testng.SuiteRunnerWorker.run(SuiteRunnerWorker.java:95)
at org.testng.TestNG.runSuitesSequentially(TestNG.java:1256)
at org.testng.TestNG.runSuitesLocally(TestNG.java:1176)
at org.testng.TestNG.runSuites(TestNG.java:1099)
at org.testng.TestNG.run(TestNG.java:1067)
at org.testng.remote.AbstractRemoteTestNG.run(AbstractRemoteTestNG.java:115)
at org.testng.remote.RemoteTestNG.initAndRun(RemoteTestNG.java:251)
at org.testng.remote.RemoteTestNG.main(RemoteTestNG.java:77)
]]>
    </failure>
  </testcase> <!-- add_New_Data_with_invalid_data2 -->
  <system-out>
    <![CDATA[<img src='file://D:\Bootcamp\jcb\Screenshot\Error_20220714_231117.PNG'height="350" width="792"/>]]>
  </system-out>
</testsuite> <!-- com.nexsoft.jcb.test.TestFiturAddNewDataPage -->
